Workbook

Sheet Introduction
B5: THIS WORKSHEET HAS BEEN PREPARED TO DEVELOP AN UNSECURED RETAIL LENDING
B6: CONTENT OF SAS CREDIT ORIGINATIONS SOLUTION
B10: 45226
B11: Draft Version

Sheet Product Strategy
A2: The product strategy definition can be parametrized. Currently the strategy includes 2 products and the strategy limits are part of the parameters definition
A4: Product Strategy | B4: Description | C4: Notes for ID Implementation
A5: Product Types Offered | B5: Personal Loan - Unsecured General Purpose Loan for Everyone - seperated into new-to-bank and existing customer flows Student Loan - 0% interest loan for students | C5: One decision flow covering all sub-products. Sub-products are managed with "requsted product code" field coming from Application System Product Strategy Decision Flow: 3 service calls for each flow: App.Call No = 1 => PL_Call1 App. Call No = 2 => PL_Call2 App. Call No = 3 => PL_Call3 Requested Product Codes: PL1 : Personal Loan PL2 : Student Loan
A6: Min Loan Amount | B6: 10,000 for PL1 5,000 for PL2 | C6: Constant assignment table
A7: Max Loan Amount | B7: 100,000 for PL1 50,000 for PL2 | C7: Constant assignment table
A8: Currency | B8: USD | C8: Let's assume all currencies of amounts in input and output are in USD
A9: Min Tenor | B9: 6 months for PL1 1 month for PL2 | C9: Constant assignment table
A10: Max Tenor | B10: 60 months for PL1 48 month for PL2 | C10: Constant assignment table
A11: Approval Authority (based on exposure) | B11: Loan Amount >50,000 goes to Credit Committee Loan Amount >80,000 goes to Group Retail Committee | C11: Constant assignment table
A12: Guarantor / Co-borrower Requirement | B12: Not required, as product is unsecured
A67: 62 (If pensioner loan 75)
A68: 67 (If pensioner loan 75)
A77: 6000 | B77: (It needs surety for all amounts)

Sheet Call Flows
A1: Call 1
A2: Description | B2: Personal Loans Flow Call 1: Credit Policy Knock-outs
A4: No | B4: Category | C4: Decision Flow Property | D4: Description
A5: 1 | B5: Rules / Table | C5: Initialization | D5: To set all decisions default to "Accept" and all ID outputs and calculated variables to default values For example, Income Calculation.Calculated Monthly Net Income = 0, LPA.Payment Plan Type.Accept Requested Payment Plan Type Flag = N …etc all numeric variables should be initialized to 0. Please check the data dictionary for default values of alphanumeric fields
A6: =A5+1 -> 2 | B6: Table | C6: Min Age | D6: To set minimum age requirements
A7: =A6+1 -> 3 | B7: Table | C7: Max Age | D7: To set maximum age requirements
A8: =A7+1 -> 4 | B8: Table | C8: Min Income | D8: To set minimum income requirement
A9: =A8+1 -> 5 | B9: Table | C9: Min Loan Amount | D9: To set minimum loan amount
A10: =A9+1 -> 6 | B10: Table | C10: Max Loan Amount | D10: To set maximum loan amount
A11: =A10+1 -> 7 | B11: Table | C11: Min Tenor | D11: To set minimum tenor
A12: =A11+1 -> 8 | B12: Table | C12: Max Tenor | D12: To set maximum tenor
A13: =A12+1 -> 9 | B13: Model Studio | C13: Application Scorecard | D13: To calculate the application score
A14: =A13+1 -> 10 | B14: Model Studio | C14: Behavior Scorecard | D14: To calculate the behavior score
A15: =A14+1 -> 11 | B15: Table | C15: Credit Risk Segmentation | D15: To assign the credit risk segment based on credit bureau and application / behavior score
A16: =A15+1 -> 12 | B16: Table | C16: Maximum Income Multiplier | D16: To set MIM
A17: =A16+1 -> 13 | B17: Table | C17: Maximum Unsecured Exposure | D17: To set maximum MUE
... A23: =A22+1 -> 19 | B23: Rules | C23: Final Decision | D23: To set the final decision based on triggered rules (accept, decline or refer)
A25: Call 2
A26: Description | B26: Personal Loans Flow Call 2: Minimum Eligibility Checks
A28: No | B28: Category | C28: Decision Flow Property | D28: Description
A29: 1 | B29: Rules / Table | C29: Initialization | D29: To set all decisions default to "Accept" and all ID outputs and calculated variables to default values For example, Income Calculation.Calculated Monthly Net Income = 0, LPA.Payment Plan Type.Accept Requested Payment Plan Type Flag = N …etc all numeric variables should be initialized to 0. Please check the data dictionary for default values of alphanumeric fields
A30: =A29+1 -> 2 | B30: Table | C30: Min Age | D30: To set minimum age requirements
A31: =A30+1 -> 3 | B31: Table | C31: Max Age | D31: To set maximum age requirements
A32: =A31+1 -> 4 | B32: Table | C32: Min Income | D32: To set minimum income requirement
A33: =A32+1 -> 5 | B33: Table | C33: Min Loan Amount | D33: To set minimum loan amount
A34: =A33+1 -> 6 | B34: Table | C34: Max Loan Amount | D34: To set maximum loan amount
A35: =A34+1 -> 7 | B35: Table | C35: Min Tenor | D35: To set minimum tenor
A36: =A35+1 -> 8 | B36: Table | C36: Max Tenor | D36: To set maximum tenor
A37: =A36+1 -> 9 | B37: Model Studio | C37: Application Scorecard | D37: To calculate the application score
A38: =A37+1 -> 10 | B38: Model Studio | C38: Behavior Scorecard | D38: To calculate the behavior score
A39: =A38+1 -> 11 | B39: Table | C39: Credit Risk Segmentation | D39: To assign the credit risk segment based on credit bureau and application / behavior score
A40: =A39+1 -> 12 | B40: Table | C40: Maximum Income Multiplier | D40: To set MIM
A41: =A40+1 -> 13 | B41: Table | C41: Maximum Unsecured Exposure | D41: To set maximum MUE
... A50: =A49+1 -> 22 | B50: Rules | C50: Final Decision | D50: To set the final decision based on triggered rules (accept, decline or refer)
A52: Call 3
A53: Description | B53: Personal Loans Flow Call 3: Final Credit Decision
A55: No | B55: Category | C55: Decision Flow Property | D55: Description
A56: 1 | B56: Rules / Table | C56: Initialization | D56: To set all decisions default to "Accept" and all ID outputs and calculated variables to default values For example, Income Calculation.Calculated Monthly Net Income = 0, LPA.Payment Plan Type.Accept Requested Payment Plan Type Flag = N …etc all numeric variables should be initialized to 0. Please check the data dictionary for default values of alphanumeric fields
A57: =A56+1 -> 2 | B57: Table | C57: Min Age | D57: To set minimum age requirements
A58: =A57+1 -> 3 | B58: Table | C58: Max Age | D58: To set maximum age requirements
...

Sheet Tables
A1: These tables should be ready in the template content and be editable by the client teams at parametere level.
A2: For example, in this demo and example content, we are setting min age to 21, but client should be able to set it to 18 after purchase.
A3: Number and type of products should be able to be multiplicated as well.
A5: Table: | B5: Min Age
A6: Description: | B6: To set minimum age policy requirements
A8: Requested Product Code | B8: Min Age
A9: PL1 | B9: 20
A10: PL2 | B10: 16
A12: Table: | B12: Max Age
A13: Description: | B13: To set maximum age policy requirements
A15: Requested Product Code | B15: Max Age
A16: PL1 | B16: 65
A17: PL2 | B17: 30
A19: Table: | B19: Min Income
A20: Description: | B20: To set minimum income policy requirements
A22: Requested Product Code | B22: Min Income (monthly net)
A23: PL1 | B23: 2000
A24: PL2 | B24: 0
A26: Table: | B26: Min Loan Amount
A27: Description: | B27: To set minimum loan amount policy requirements
A29: Requested Product Code | B29: Min Loan Amount
A30: PL1 | B30: 10000
A31: PL2 | B31: 5000
A33: Table: | B33: Max Loan Amount
A34: Description: | B34: To set maximum loan amount policy requirements
A36: Requested Product Code | B36: Max Loan Amount
A37: PL1 | B37: 100000
A38: PL2 | B38: 50000
A40: Table: | B40: Min Tenor
A41: Description: | B41: To set minimum tenor policy requirements
A43: Requested Product Code | B43: Min Tenor
A44: PL1 | B44: 6
A45: PL2 | B45: 1
A47: Table: | B47: Max Tenor
A48: Description: | B48: To set maximum tenor policy requirements
A50: Requested Product Code | B50: Max Tenor
A51: PL1 | B51: 60
A52: PL2 | B52: 48
A54: Decision Table: | B54: Credit Risk Segmentation
A55: Description: | B55: Assigns the credit risk segment based on available scoring models, this could be updated according with cut off and scores chosen as well with characteristics of the credit bureau score
...

Sheet Scorecards
A1: Scorecard | B1: Application Scorecard
A2: Description: | B2: Expert Application Scorecard developed for originations decisions of Personal Loans in case required, but the methodology used was based on score models
A4: Characteristics | B4: Range | C4: Score | E4: Min Score | F4: Max Score
A5: Age | B5: < 18 Years | C5: 10 | D5: CUSTOMER_AGE | E5: =C11+C20+C27+C32+C45+C48+C54+C61+C71 -> 72 | F5: =C8+C12+C25+C28+C35+C51+C55+C65+C68 -> 254
B6: 18 - 30 Years | C6: 20
B7: 30 - 40 Years | C7: 30
B8: 40 - 50 Years | C8: 45
B9: 50+ years | C9: 40
B10: No Information | C10: 30
B11: No response | C11: 10
A12: Residential Status | B12: Belongs to Customer | C12: 35 | D12: RESIDENCE_STATUS
B13: Mortgage | C13: 30
B14: Co-Owner | C14: 25
B15: Belongs to Family | C15: 23
B16: Belongs to Someone Else | C16: 20
B17: Rent | C17: 15
B18: Other | C18: 10
B19: No Information | C19: 23
B20: No response | C20: 10
A21: Time in Current Employment (months) | B21: Less than 12 Months | C21: 10 | D21: TOTAL_EMPLOYMENT_DURATION
B22: 12 to < 24 Months | C22: 18
B23: 24 to < 48 Months | C23: 23
B24: 48 to < 60 Months | C24: 25
B25: > 60 Months | C25: 30
B26: No Information | C26: 23
B27: No response | C27: 10
A28: Marital Status | B28: Married | C28: 28 | D28: MARITAL_STATUS
B29: Widowed | C29: 20
B30: Engaged \ Co-Living | C30: 18
B31: Divorced | C31: 15
B32: Single | C32: 8
B33: No Information | C33: 18
B34: No response | C34: 8
A35: Employment Status | B35: Public Sector salaried | C35: 28 | D35: CUSTOMER_EMPLOYMENT_TYPE
B36: Private Sector salaried | C36: 25
B37: Banking / Financial Institution Salaried | C37: 25
B38: Trade | C38: 20
B39: Self-employed Professional | C39: 20
B40: Owner/Shareholder | C40: 20
B41: Farmer | C41: 15
...

Sheet Scores
A1: Scorecard | B1: Application Scorecard
A2: Description: | B2: Application score build based on random forest
A4: BUREAU_SCORE
A5: CUSTOMER_EMPLOYMENT_TYPE
A6: DOCUMENTED_INCOME
A7: PRODUCT_CODE
A10: Scorecard | B10: Behavioral Score
A11: Description: | B11: Build with VDMML using the risk add on scorecard and interactive groupng
A14: BUREAU_CARD_UTILIZATION
A15: BUREAU_SCORE
A16: CUSTOMER_AGE
A17: CUSTOMER_EMPLOYMENT_TYPE
A18: CUSTOMER_MONTH_EXPENCES
A19: DECLARE_INCOME
A20: DOCUMENTED_INCOME
A21: WPS_AUTO_LOAN_LAST_!"M
A22: WPS_CARD_LOAN_LAST_!"M
A23: WPS_LOAN_LOAN_LAST_!"M
A24: WPS_MORTGAGE_LOAN_LAST_!"M
A25: WPS_OD_LOAN_LAST_!"M
... A29: TOTAL_NON_CARD_BALANCE
A31: Existing Customer Flag | B31: Behavior Score | C31: Application Score | D31: Credit Bureau Score | E31: Credit Risk Segment | F31: Definition
A32: Y | B32: >= 247 | E32: VL | F32: Very low risk
A33: Y | B33: 203-246 | E33: LO | F33: Low risk
A34: Y | B34: 178-202 | D34: >= 768 | E34: LO | F34: Low risk
A35: Y | B35: 178-202 | D35: 562-767 | E35: LO | F35: Low risk
A36: Y | B36: 178-202 | D36: 426-561 | E36: ME | F36: Medium risk
A37: Y | B37: 178-202 | D37: 233-425 | E37: ME | F37: Medium risk
A38: Y | B38: 178-202 | D38: <= 232 | E38: HI | F38: High Risk
A39: Y | B39: 167-177 | D39: >= 768 | E39: LO | F39: Low risk
A40: Y | B40: 167-177 | D40: 562-767 | E40: ME | F40: Medium risk
A41: Y | B41: 167-177 | D41: 426-561 | E41: ME | F41: Medium risk
A42: Y | B42: 167-177 | D42: 233-425 | E42: HI | F42: High Risk
A43: Y | B43: 167-177 | D43: <= 232 | E43: VH | F43: Very high risk
A44: Y | B44: 0-166 | D44: >= 768 | E44: ME | F44: Medium risk
A45: Y | B45: 0-166 | D45: 562-767 | E45: HI | F45: High Risk
... A48: Y | B48: 0-166 | D48: <= 232 | E48: VH | F48: Very high risk
A49: N | C49: <= 0.026 | D49: >= 768 | E49: VL | F49: Very low risk
A50: N | C50: <= 0.026 | D50: 562-767 | E50: VL | F50: Very low risk
A51: N | C51: <= 0.026 | D51: 426-561 | E51: LO | F51: Very low risk
...

Sheet Rules
B1: Ruleset: | C1: Initialization
B3: Rule Name | C3: Description | D3: Logic
B4: Default | C4: Initialization of decisions, output fields and calculated variables to their default figures to avoid system error | D4: To set all decisions default to "Accept" and all ID outputs and calculated variables to default values For example: Income Calculation.Calculated Monthly Net Income = 0, LPA.Payment Plan Type.Accept Requested Payment Plan Type Flag = N …etc all numeric variables should be initialized to 0. Please check the data dictionary for default values of alphanumeric fields
B5: Up-sell | C5: Determines if customer is eligible for up-sell | D5: If Risk Segmentation.Risk Segment = VL, Upsell_Flag = Y, else Upsell_Flag = N
B6: WPS_L12M | C6: Deriving "Worst CB Delinquency Status Last 12 Months (dpd)" scorecard characteristic from product level data dictionary keys | D6: WPS_L12M = Max(App.WPS Card Last 12M, App.WPS Loan Last 12M, App.WPS Mortgage Last 12M, App.WPS Auto Loan Last 12M, App.WPS OD Last 12M)
B8: Ruleset: | C8: Credit Policy Rules in call flow item: Credit Policy Rules Call 1
B10: Rule Name | C10: Description | D10: Logic | E10: Decision | F10: Reason Code
B11: Unemployed | C11: Customer is unemployed | D11: If Product code = PL1 and Employment Type = U, R, H, T | E11: Decline | F11: D101
B12: Min Income | C12: Customer's income is below policy minimum | D12: If Product code = PL1 and Declared Income < Minimum Income | E12: Decline | F12: D102
B13: Permanent Residency | C13: Customer is not a permanent resident of Country | D13: If Permanent Residence Flag = N | E13: Decline | F13: D103
B14: Pledged Account | C14: Customer has a blocked account at the bank | D14: If Pledged Amount>1000 | E14: Decline | F14: D104
B15: Min Age | C15: Customer's age is below policy minimum | D15: If Product code = PL1 and Customer's Age< 20 else if Product code = PL2 and Customer's Age < 17 | E15: Decline | F15: D105
B16: Max Age | C16: Customer is above maximum | D16: If Age > Maximum Age | E16: Decline | F16: D106
B17: Non-target_Market | C17: Customer is not in the target market of personal loans | D17: If Employment Type is in { E, O, F, M} | E17: Decline | F17: D107
B18: Job Duration | C18: Customer's job duration is less than policy minimum | D18: If Total Employment Duration < 6 and App.Employment Type = P,S,L,O,F,B | E18: Decline | F18: D108
B19: Customer has a bank legal follow up | C19: Customer has defaulted in payments and a legal follow up is initiated by the bank (in house) | D19: If App.Customer status is in L,S,W,A,R,V | E19: Decline | F19: D109
B20: Current Delinquency | C20: If customer has current delays > 30 days for any credit product at the bank (credit card, loans, overdraft etc) | D20: If Current 30 dpd number of Credit Cards>0, or Current 30 dpd number of Personal Loans>0, or Current 30 dpd number of Auto Loans>0, or Current 30 dpd number of Mortgages>0, or Current 30 dpd number of Cash Collateral>0, or Current 30 dpd number of Overdrafts>0 | E20: Decline | F20: D110
B22: Ruleset: | C22: Output Fields Call 1
B23: Rule Name | C23: Description | D23: Logic
B24: Credit Bureau Check | C24: If customer has a fresh credit bureau data, no need to do a credit bureau inquiry | D24: If Bureau Investigation Date Since>0 and Bureau Investigation Date Since<10 then call Credit Bureau with return variable CALL_BUREAU = N, else Y.
B25: Random Number | C25: To be used in champion/challenger strategy setup. RAND function should be used to create a random number between 1 to 999. | D25: Random Number = RAND()
B27: Ruleset: | C27: Credit Policy Rules in call flow item: Credit Policy Rules Call 2
B29: Rule Name | C29: Description | D29: Logic | E29: Decision | F29: Decision Reason Code
B30: Customer has a bureau legal follow up | C30: Customer has defaulted in payments and a legal follow up is initiated by the bank at credit bureau | D30: If App.WPS (Worst Payment Status) Ever = L | E30: Decline | F30: D111
B31: Very High Risk Segment | C31: According to application score x bureau score policy or behavior score x bureau score policy, score is below minimum or customer risk gement is very high | D31: If Risk Segmentation.Risk Segment = VH | E31: Decline | F31: D112
B32: No Disposable_Income | C32: Declines if there is no room in customer's current disposable income | D32: If Income Calculation.Disposable Net Income <= 0 | E32: Decline | F32: D113
B33: High Maximum_Unsecured_Exposure | C33: Declines if customer's total unsecured exposure is above policy | D33: If Limit Calculation.CustomerUnsecuredExposure> Limit Calculation.MaxCustomerUnsecuredExposure | E33: Decline | F33: D114
B34: Below Min Limit / No Room for Loan | C34: Credit limit calculated for the customer is below product minimum | D34: If Limit Calculation.App.Suggested Loan Amount<LPA.Min loan amount | E34: Decline | F34: D115
B35: High Debt Burden | C35: Debt burden calculated is higher than maximum allowed debt burden | D35: If Limit Calculation.Debt Burden Ratio > Max Debt Burden.Max Debt Burden | E35: Decline | F35: D116
B36: Credit Committee Approval | C36: Loan Amount >50,000 goes to Credit Committee | D36: If Limit Calculation.App.Suggested Loan Amount > 50000 | E36: Refer | F36: R101
B37: Group Retail Committee Approval | C37: Loan Amount >80,000 goes to Group Retail Committee | D37: If Limit Calculation.App.Suggested Loan Amount > 80000 | E37: Refer | F37: R102
B38: Customer is a staff | C38: If customer is bank's staff, HR view is required | D38: If App.Application.Staff Flag = Y | E38: Refer | F38: R104
B39: verification_needed | C39: If verification is needed for that account, OMDM sends this flag Y and PEGA parks the application for manual review | D39: If Verification Decision.Decision=Y and Verification Completed Flag=N | E39: Refer | F39: R105
B40: documentation_needed | C40: If further documentation is required, OMDM sends this flag Y and PEGA parks the application for manual review | D40: If Documentation Decision.Decision=Y and Documentation Completed Flag=N | E40: Refer | F40: R106
B41: fraud_control_main applicant | C41: Customer has an inconsistency in application information with previous applications | D41: If Home city inconsistency flag for main applicant = Y OR Business/work city inconsistency flag for main applicant = Y OR Email inconsistency flag for main applicant = Y OR Mother's maiden name inconsistency flag for main applicant = Y | E41: Refer | F41: R107 | G41: App.Bureau Fraud Flag
B44: Ruleset: | C44: Credit Policy Rules in call flow item: Credit Policy Rules Call 3 - REPEAT OF POLICY DECLINES IN CALL 1 AND 2
B46: Rule Name | C46: Description | D46: Logic | E46: Decision | F46: Decision Reason Code
B47: Unemployed | C47: Customer is unemployed | D47: If Product code = PL1 and Employment Type = U, R, H, T | E47: Decline | F47: D101
B48: Min Income | C48: Customer's income is below policy minimum | D48: If Product code = PL1 and Declared Income < Minimum Income | E48: Decline | F48: D102
B49: Permanent Residency | C49: Customer is not a permanent resident of Country | D49: If Permanent Residence Flag = N | E49: Decline | F49: D103
...

Sheet Sheet1

Sheet Data Dictionary_All
A1: SAS ID UNSECURED LOAN ORIGINATIONS - DATA DICTIONARY
A2: No | B2: Data Field Name | C2: Data Field Description | D2: Used in a Rule - Name | E2: SAS ID variable name | F2: Data Category | G2: Valid Values | H2: Default Value | I2: Format | J2: Lenght | K2: Precision | L2: Array Size | M2: Mapped / Calculated | N2: Batch / Online | O2: 1.Service | P2: 2.Service | Q2: 3. Service
A3: 1 | B3: Application type | C3: In future there may be a pre-selection / pre-approval process and we may need to design a separate flow for such applications using this flag | F3: Application | G3: N:Normal, B: Batch, S: Speedy | H3: " " | I3: Alpha | J3: 1 | K3: 0 | L3: 0 | M3: M | N3: O | O3: I | P3: I | Q3: I
A4: =A3+1 -> 2 | B4: No of Sub-applications | C4: In future, there may be bundle product offers and in one application form, customer may apply for both loan and card. In this case, this variable keeps number of products requested in a single application form. | F4: Application | G4: Numeric | H4: 0 | I4: Numeric | J4: 4 | K4: 0 | L4: 0 | M4: M | N4: O | O4: I | P4: I | Q4: I
A5: =A4+1 -> 3 | B5: Channel | C5: Sales channel the application is received. | F5: Application | G5: Pls. refer to "Parameters" sheet | H5: " " | I5: Alpha | J5: 2 | K5: 0 | L5: 0 | M5: M | N5: O | O5: I | P5: I | Q5: I
A6: =A5+1 -> 4 | B6: Call No | C6: Decision engine call number | E6: CALL_ID | F6: Application | G6: 1,2,3 | H6: " " | I6: Numeric | J6: 1 | K6: 0 | L6: 0 | M6: M | N6: O | O6: I | P6: I | Q6: I
A7: =A6+1 -> 5 | B7: Country | C7: Country the application is received from | F7: Application | H7: " " | I7: Alpha | J7: 2 | K7: 0 | L7: 0 | M7: M | N7: O | O7: I | P7: I | Q7: I
A8: =A7+1 -> 6 | B8: ID Confirmation Flag | C8: Should be Y if customer's ID information is verified (KYC) | F8: Application | G8: Y/N | H8: N | I8: Alpha | J8: 1 | K8: 0 | L8: 0 | M8: M | N8: O | O8: I | P8: I | Q8: I
A9: =A8+1 -> 7 | B9: ID non-confirmation reason | C9: If ID information cannot be verified, the reason code for this | F9: Application | G9: Should be the values kept in Core System | H9: " " | I9: Alpha | J9: 2 | K9: 0 | L9: 0 | M9: M | N9: O | O9: I | P9: I | Q9: I
A10: =A9+1 -> 8 | B10: Pre-approved flag | C10: In future, for a pre-approval process, if application is from a pre-approved list, this flag should be Y | F10: Application | G10: Y/N | H10: N | I10: Alpha | J10: 1 | K10: 0 | L10: 0 | M10: M | N10: O | O10: I | P10: I | Q10: I
A11: =A10+1 -> 9 | B11: Random Number | C11: Random number generated by ID for challenger strategy development | E11: RANDOM_ID | F11: Application | G11: Numeric | H11: N/A | I11: Numeric | J11: 3 | K11: 0 | L11: 0 | M11: M | N11: O | O11: I | P11: I | Q11: I
A12: =A11+1 -> 10 | B12: Deviation flag | C12: If the application has been requested to be deviated on Core System. This flag should be on Core System screen and manually turned to Y in Core System. | F12: Application | G12: Y/N | H12: N | I12: Alpha | J12: 1 | K12: 0 | L12: 0 | M12: M | N12: O | O12: I | P12: I | Q12: I
A13: =A12+1 -> 11 | B13: Deviation Reason Codes | C13: For applications where Deviation Flag = Y, Core System should send the decline reason codes from ID's previous calls (and or same call's previous call) in an array | F13: Application | G13: ID Reason codes and explanations will be provided after strategy setup. These codes will be kept in Core System and be converted to explanations to be displayed on Core System screen. | H13: " " | I13: Alpha | J13: 4 | K13: 0 | L13: 10 | M13: M | N13: O | O13: I | P13: I | Q13: I
A14: =A13+1 -> 12 | B14: Sorted Reason Codes1 | C14: The array sent by ID in C1.Policy Rules.Sorted Reason Codes result field is sent back to ID. (If that call is processed more than once, the final status of the array should be sent) | F14: Application | G14: ID Reason codes and explanations will be provided after strategy setup. These codes will be kept in Core System and be converted to explanations to be displayed on Core System screen. | H14: " " | I14: Alpha | J14: 4 | K14: 0 | L14: 10 | M14: M | N14: O | O14: I | P14: I | Q14: I
A15: =A14+1 -> 13 | B15: Sorted Decision Table1 | C15: The array sent by ID in C1.Policy Rules.Sorted Decisions result field is sent back to ID. (If that call is processed more than once, the final status of the array should be sent) | F15: Application | H15: " " | I15: Alpha | J15: 4 | K15: 0 | L15: 10 | M15: M | N15: O | O15: I | P15: I | Q15: I
A16: =A15+1 -> 14 | B16: Sorted Reason Codes2 | C16: The array sent by ID in C2.Policy Rules.Sorted Reason Codes result field is sent back to ID. (If that call is processed more than once, the final status of the array should be sent) | F16: Application | H16: " " | I16: Alpha | J16: 4 | K16: 0 | L16: 10 | M16: M | N16: O | O16: I | P16: I | Q16: I
A17: =A16+1 -> 15 | B17: Sorted Decision Table2 | C17: The array sent by ID in C2.Policy Rules.Sorted Decisions result field is sent back to ID. (If that call is processed more than once, the final status of the array should be sent) | F17: Application | H17: " " | I17: Alpha | J17: 4 | K17: 0 | L17: 10 | M17: M | N17: O | O17: I | P17: I | Q17: I
A18: =A17+1 -> 16 | B18: Sorted Reason Codes3 | C18: The array sent by ID in C3.Policy Rules.Sorted Reason Codes result field is sent back to ID. (If that call is processed more than once, the final status of the array should be sent) | F18: Application | H18: " " | I18: Alpha | J18: 4 | K18: 0 | L18: 10 | M18: M | N18: O | O18: I | P18: I | Q18: I
A19: =A18+1 -> 17 | B19: Sorted Decision Table3 | C19: The array sent by ID in C3.Policy Rules.Sorted Decisions result field is sent back to ID. (If that call is processed more than once, the final status of the array should be sent) | F19: Application | H19: " " | I19: Alpha | J19: 4 | K19: 0 | L19: 10 | M19: M | N19: O | O19: I | P19: I | Q19: I
A20: =A19+1 -> 18 | B20: S_opinion | C20: Suspicious Opinion from Sales (KYC purposes) - Y if application is suspicious | F20: Application | G20: Y/N | H20: N | I20: Alpha | J20: 1 | K20: 0 | L20: 0 | M20: M | N20: O | O20: I | P20: I | Q20: I
A21: =A20+1 -> 19 | B21: Permanent Residence Flag | C21: Customer is a permanent resident | D21: Permanent Residence Flag | E21: PERMANENT_RESIDENT_FLG | F21: Application | G21: Y/N | H21: N | I21: Alpha | J21: 1 | K21: 0 | L21: 0 | M21: M | N21: O | O21: I | P21: I | Q21: I
A22: =A21+1 -> 20 | B22: Overtime flag | C22: If the application has received beyond working hours, this should be Y. | F22: Application | G22: Y/N | H22: N | I22: Alpha | J22: 1 | K22: 0 | L22: 0 | M22: M | N22: O | O22: I | P22: I | Q22: I
A23: =A22+1 -> 21 | B23: App.ID_Document_Flag | C23: This will be Y if ID document is completed | F23: Individual Customer | G23: Y/N | H23: N | I23: Alpha | J23: 1 | K23: 0 | L23: 0 | M23: M | N23: O | O23: I | P23: I | Q23: I
A24: =A23+1 -> 22 | B24: App.Address_Document_Flag | C24: This will be Y if Adress document is completed | F24: Individual Customer | G24: Y/N | H24: N | I24: Alpha | J24: 1 | K24: 0 | L24: 0 | M24: M | N24: O | O24: I | P24: I | Q24: I
A25: =A24+1 -> 23 | B25: App.Foreigner_Document_Flag | C25: This will be Y if Foreigner document is completed | F25: Individual Customer | G25: Y/N | H25: N | I25: Alpha | J25: 1 | K25: 0 | L25: 0 | M25: M | N25: O | O25: I | P25: I | Q25: I
A26: =A25+1 -> 24 | B26: App.Credit Bureau Completed Flag | C26: This will be Y if credit registry check is completed | F26: Individual Customer | G26: Y/N | H26: N | I26: Alpha | J26: 1 | K26: 0 | L26: 0 | M26: M | N26: O | O26: I | P26: I | Q26: I
A27: =A26+1 -> 25 | B27: Derived.Random Number | C27: Calculated by ID and sent to Core System | D27: Derived.Random Number | E27: DERIVED_RANDOM_NUMBER | F27: ID Output | G27: Numeric | H27: 0 | I27: Numeric | J27: 3 | K27: 0 | L27: 0 | M27: ID | N27: O | O27: O | P27: O | Q27: O
A28: =A27+1 -> 26 | B28: Income Calculation.Calculated Monthly Net Income | C28: Calculated by ID and sent to Core System | D28: Income Calculation.Calculated Monthly Net Income | E28: MONTHLY_NET_INCOME | F28: ID Output | G28: Numeric | H28: 0 | I28: Numeric | J28: 12 | K28: 2 | L28: 0 | M28: ID | N28: O | O28: O | P28: O | Q28: O
A29: =A28+1 -> 27 | B29: App.Income Document flag | C29: Y if income document is provided with application | E29: VERIFIED_DOCUMENT_INCOME_FLG | F29: Individual Customer | G29: Y/N | H29: N | I29: Alpha | J29: 1 | K29: 0 | L29: 0 | M29: M | N29: O | O29: I | P29: I | Q29: I
A30: =A29+1 -> 28 | B30: App.Verification Completed Flag | C30: Y if verification is completed (Zeynep 02.03.2023) | E30: VERIFICATION_COMPLETED_FLG | F30: Individual Customer | G30: Y/N | H30: N | I30: Alpha | J30: 1 | K30: 0 | L30: 0 | M30: M | N30: O | O30: I | P30: I | Q30: I
A31: =A29+1 -> 28 | B31: Income Calculation.Disposable Net Income | C31: Calculated by ID and sent to Core System | D31: Income Calculation.Disposable Net Income | E31: DISPOSABLE_NET_INCOME | F31: ID Output | G31: Numeric | H31: 0 | I31: Numeric | J31: 12 | K31: 2 | L31: 0 | M31: ID | N31: O | O31: O | P31: O | Q31: O
A32: =A31+1 -> 29 | B32: App.Documented Income fx | C32: Currency of the income on the income document | F32: Individual Customer | H32: " " | I32: Alpha | J32: 2 | K32: 0 | L32: 0 | M32: M | N32: O | O32: I | P32: I | Q32: I
A33: =A32+1 -> 30 | B33: App.Other Income | C33: Other income (if any provided) | E33: OTHER_INCOME | F33: Individual Customer | G33: Numeric | H33: 0 | I33: Numeric | J33: 10 | K33: 0 | L33: 0 | M33: M | N33: O | O33: I | P33: I | Q33: I
A34: =A33+1 -> 31 | B34: App.Other Income Fx | C34: Currency of other income (if any provided) | F34: Individual Customer | H34: " " | I34: Alpha | J34: 2 | K34: 0 | L34: 0 | M34: M | N34: O | O34: I | P34: I | Q34: I
A35: =A34+1 -> 32 | B35: App.Other Income Type | C35: Explanation / Type of the income stated as other (spouse income, rent income..etc) | F35: Individual Customer | G35: Pls. refer to "Parameters" sheet | H35: " " | I35: Alpha | J35: 1 | K35: 0 | L35: 0 | M35: M | N35: O | O35: I | P35: I | Q35: I
A36: =A35+1 -> 33 | B36: App.Other Income Duration | C36: Duration of the other income received (months) | F36: Individual Customer | G36: Numeric | H36: 0 | I36: Numeric | J36: 3 | K36: 0 | L36: 0 | M36: M | N36: O | O36: I | P36: I | Q36: I
A37: =A36+1 -> 34 | B37: Max Debt Burden.Max Debt Burden | C37: Calculated by ID and sent to Core System | D37: Max Debt Burden.Max Debt Burden | E37: MAX_DEBT_BURDEN | F37: ID Output | G37: Numeric | H37: 0 | I37: Numeric | J37: 3 | K37: 2 | L37: 0 | M37: ID | N37: O | O37: O | P37: O | Q37: O
A38: =A37+1 -> 35 | B38: App.Nationality | C38: Customer's nationality | F38: Individual Customer | G38: Pls. refer to "Parameters" sheet | H38: " " | I38: Alpha | J38: 2 | K38: 0 | L38: 0 | M38: M | N38: O | O38: I | P38: I | Q38: I
A39: =A38+1 -> 36 | B39: App.Citizenship No | C39: Cusomer's nationality number | F39: Individual Customer | G39: Numeric | H39: 0 | I39: Alpha | J39: 10 | K39: 0 | L39: 0 | M39: M | N39: O | O39: I | P39: I | Q39: I
A40: =A39+1 -> 37 | B40: App.Tax Number | C40: Cusomer's tax number | F40: Individual Customer | G40: Numeric | H40: 0 | I40: Alpha | J40: 10 | K40: 0 | L40: 0 | M40: M | N40: O | O40: I | P40: I | Q40: I
...

Sheet Data Dictionary Used
A1: SAS ID UNSECURED LOAN ORIGINATIONS - DATA DICTIONARY
A2: No | B2: Data Field Name | C2: Data Field Description | D2: Used in a Rule - Name | E2: SAS ID variable name | F2: Data Category | G2: Valid Values | H2: Default Value | I2: Format | J2: Lenght | K2: Precision | L2: Array Size | M2: Mapped / Calculated | N2: Batch / Online | O2: 1.Service | P2: 2.Service | Q2: 3. Service
A3: 1 | B3: Application type | C3: In future there may be a pre-selection / pre-approval process and we may need to design a separate flow for such applications using this flag | F3: Application | G3: N:Normal, B: Batch, S: Speedy | H3: " " | I3: Alpha | J3: 1 | K3: 0 | L3: 0 | M3: M | N3: O | O3: I | P3: I | Q3: I
A4: =+A3+1 -> 2 | B4: Call No | C4: Decision engine call number | E4: CALL_ID | F4: Application | G4: 1,2,3 | H4: " " | I4: Numeric | J4: 1 | K4: 0 | L4: 0 | M4: M | N4: O | O4: I | P4: I | Q4: I
A5: =+A4+1 -> 3 | B5: Random Number | C5: Random number generated by ID for challenger strategy development | E5: RANDOM_ID | F5: Application | G5: Numeric | H5: N/A | I5: Numeric | J5: 3 | K5: 0 | L5: 0 | M5: M | N5: O | O5: I | P5: I | Q5: I
A6: =+A5+1 -> 4 | B6: Permanent Residence Flag | C6: Customer is a permanent resident | D6: Permanent Residence Flag | E6: PERMANENT_RESIDENT_FLG | F6: Application | G6: Y/N | H6: N | I6: Alpha | J6: 1 | K6: 0 | L6: 0 | M6: M | N6: O | O6: I | P6: I | Q6: I
A7: =+A6+1 -> 5 | B7: Derived.Random Number | C7: Calculated by ID and sent to Core System | D7: Derived.Random Number | E7: DERIVED_RANDOM_NUMBER | F7: ID Output | G7: Numeric | H7: 0 | I7: Numeric | J7: 3 | K7: 0 | L7: 0 | M7: ID | N7: O | O7: O | P7: O | Q7: O
A8: =+A7+1 -> 6 | B8: Income Calculation.Calculated Monthly Net Income | C8: Calculated by ID and sent to Core System | D8: Income Calculation.Calculated Monthly Net Income | E8: MONTHLY_NET_INCOME | F8: ID Output | G8: Numeric | H8: 0 | I8: Numeric | J8: 12 | K8: 2 | L8: 0 | M8: ID | N8: O | O8: O | P8: O | Q8: O
A9: =+A8+1 -> 7 | B9: App.Income Document flag | C9: Y if income document is provided with application | E9: VERIFIED_DOCUMENT_INCOME_FLG | F9: Individual Customer | G9: Y/N | H9: N | I9: Alpha | J9: 1 | K9: 0 | L9: 0 | M9: M | N9: O | O9: I | P9: I | Q9: I
A10: =+A9+1 -> 8 | B10: App.Verification Completed Flag | C10: Y if verification is completed (Zeynep 02.03.2023) | E10: VERIFICATION_COMPLETED_FLG | F10: Individual Customer | G10: Y/N | H10: N | I10: Alpha | J10: 1 | K10: 0 | L10: 0 | M10: M | N10: O | O10: I | P10: I | Q10: I
A11: =+A10+1 -> 9 | B11: Income Calculation.Disposable Net Income | C11: Calculated by ID and sent to Core System | D11: Income Calculation.Disposable Net Income | E11: DISPOSABLE_NET_INCOME | F11: ID Output | G11: Numeric | H11: 0 | I11: Numeric | J11: 12 | K11: 2 | L11: 0 | M11: ID | N11: O | O11: O | P11: O | Q11: O
A12: =+A11+1 -> 10 | B12: App.Other Income | C12: Other income (if any provided) | E12: OTHER_INCOME | F12: Individual Customer | G12: Numeric | H12: 0 | I12: Numeric | J12: 10 | K12: 0 | L12: 0 | M12: M | N12: O | O12: I | P12: I | Q12: I
A13: =+A12+1 -> 11 | B13: Max Debt Burden.Max Debt Burden | C13: Calculated by ID and sent to Core System | D13: Max Debt Burden.Max Debt Burden | E13: MAX_DEBT_BURDEN | F13: ID Output | G13: Numeric | H13: 0 | I13: Numeric | J13: 3 | K13: 2 | L13: 0 | M13: ID | N13: O | O13: O | P13: O | Q13: O
A14: =+A13+1 -> 12 | B14: App.Education | C14: Customer's education level | E14: CUSTOMER_EDUCATION | F14: Individual Customer | G14: Pls. refer to "Parameters" sheet | H14: " " | I14: Alpha | J14: 1 | K14: 0 | L14: 0 | M14: M | N14: O | O14: I | P14: I | Q14: I
A15: =+A14+1 -> 13 | B15: Limit Calculation.App.Suggested Loan Amount | C15: Calculated by ID and sent to Core System | D15: Limit Calculation.App.Suggested Loan Amount | E15: SUGGESTED_LOAN_AMOUNT | F15: ID Output | G15: Numeric | H15: 0 | I15: Numeric | J15: 12 | K15: 0 | L15: 0 | M15: ID | N15: O | O15: O | P15: O | Q15: O
A16: =+A15+1 -> 14 | B16: Limit Calculation.Debt Burden Ratio | C16: Debt burden ratio calculated by ID | D16: Limit Calculation.Debt Burden Ratio | E16: DEBT_BURDEN_RATIO | F16: ID Output | G16: Numeric | H16: 0 | I16: Numeric | J16: 3 | K16: 2 | L16: 0 | M16: ID | N16: O | O16: O | P16: O | Q16: O
A17: =+A16+1 -> 15 | B17: App.Marrital Status | C17: Marrital status of the customer | E17: MARITAL_STATUS | F17: Individual Customer | G17: Pls. refer to "Parameters" sheet | H17: " " | I17: Alpha | J17: 1 | K17: 0 | L17: 0 | M17: M | N17: O | O17: I | P17: I | Q17: I
A18: =+A17+1 -> 16 | B18: App.Residence Type | C18: Ownership of the house | E18: RESIDENCE_STATUS | F18: Individual Customer | G18: Pls. refer to "Parameters" sheet | H18: " " | I18: Alpha | J18: 1 | K18: 0 | L18: 0 | M18: M | N18: O | O18: I | P18: I | Q18: I
A19: =+A18+1 -> 17 | B19: App.Rent | C19: Rent amount (if customer states s/he has rental income) | E19: RENT_INCOME | F19: Individual Customer | G19: Numeric | H19: 0 | I19: Numeric | J19: 10 | K19: 0 | L19: 0 | M19: M | N19: O | O19: I | P19: I | Q19: I
A20: =+A19+1 -> 18 | B20: Limit Calculation.CustomerUnsecuredExposure | C20: Customer MUE in bank calculated in ID | D20: Limit Calculation.CustomerUnsecuredExposure | E20: UNSECURED_EXPOSURE | F20: ID Output | G20: Numeric | H20: 0 | I20: Numeric | J20: 12 | K20: 0 | L20: 0 | M20: ID | N20: O | O20: O | P20: O | Q20: O
A21: =+A20+1 -> 19 | B21: App.No of dependents | C21: No of dependents | E21: CUSTOMER_DEPENDENTS_CNT | F21: Individual Customer | G21: Numeric | H21: 0 | I21: Numeric | J21: 3 | K21: 0 | L21: 0 | M21: M | N21: O | O21: I | P21: I | Q21: I
A22: =+A21+1 -> 20 | B22: App.Salary Tie-up Flag | C22: Flag to show if customer is already a salary tie-up customer of the bank | E22: SALARY_TIE_UP_FLG | F22: Individual Customer | G22: Y/N | H22: N | I22: Alpha | J22: 1 | K22: 0 | L22: 0 | M22: M | N22: O | O22: I | P22: I | Q22: I
A23: =+A22+1 -> 21 | B23: App.Salary Tie-up Amount | C23: Salary of the Bank's salary tie-up customer | E23: SALARY_TIE_UP_AMOUNT | F23: Individual Customer | G23: Numeric | H23: 0 | I23: Numeric | J23: 10 | K23: 0 | L23: 0 | M23: M | N23: O | O23: I | P23: I | Q23: I
A24: =+A23+1 -> 22 | B24: Limit Calculation.MaxCustomerUnsecuredExposure | C24: Max Customer MUE allowed by policy | D24: Limit Calculation.MaxCustomerUnsecuredExposure | E24: MAX_UNSECURED_EXPOSURE | F24: ID Output | G24: Numeric | H24: 0 | I24: Numeric | J24: 12 | K24: 0 | L24: 0 | M24: ID | N24: O | O24: O | P24: O | Q24: O
A25: =+A24+1 -> 23 | B25: C1.Policy Rules.Decision Category | C25: Calculated by ID and sent to Core System | D25: C1.Policy Rules.Decision Category | E25: C1_DECISION_CATEGORY | F25: ID Output | H25: " " | I25: Alpha | J25: 20 | K25: 0 | L25: 0 | M25: ID | N25: O | O25: O
A26: =+A25+1 -> 24 | B26: Risk Segmentation.Risk Segment | C26: Calculated by ID and sent to Core System | D26: Risk Segmentation.Risk Segment | E26: RISK_SEGMENT | F26: ID Output | H26: " " | I26: Alpha | J26: 2 | K26: 0 | L26: 0 | M26: ID | N26: O | P26: O | Q26: O
A27: =+A26+1 -> 25 | B27: C2.Policy Rules.Decision Category | C27: Calculated by ID and sent to Core System | D27: C2.Policy Rules.Decision Category | E27: C2_DECISION_CATEGORY | F27: ID Output | H27: " " | I27: Alpha | J27: 20 | K27: 0 | L27: 0 | M27: ID | N27: O | P27: O
A28: =+A27+1 -> 26 | B28: Requested Loan Tenor | C28: Requested Loan Tenor | E28: REQUESTED_LOAN_TENOR | F28: Requested Product | G28: Numeric | H28: 0 | I28: Numeric | J28: 3 | K28: 0 | L28: 0 | M28: M | N28: O | O28: I | P28: I | Q28: I
A29: =+A28+1 -> 27 | B29: C3.LPA.Min loan amount | C29: Calculated by ID and sent to Core System | D29: C3.LPA.Min loan amount | E29: C3_MIN_LOAN_AMOUNT | F29: ID Output | G29: Numeric | H29: 0 | I29: Numeric | J29: 12 | K29: 2 | L29: 0 | M29: ID | N29: O | Q29: O
A30: =+A29+1 -> 28 | B30: Interest Rate for 12 months | C30: Shall we retrieve this as we can offer different tenor based on eligible amount? | E30: INTEREST_RATE_12 | F30: Requested Product | G30: Numeric | H30: 0 | I30: Numeric | J30: 4 | K30: 2 | L30: 0 | M30: M | N30: O | O30: I | P30: I | Q30: I
A31: =+A30+1 -> 29 | B31: Interest Rate for 18 months | C31: Shall we retrieve this as we can offer different tenor based on eligible amount? | E31: INTEREST_RATE_18 | F31: Requested Product | G31: Numeric | H31: 0 | I31: Numeric | J31: 4 | K31: 2 | L31: 0 | M31: M | N31: O | O31: I | P31: I | Q31: I
A32: =+A31+1 -> 30 | B32: Interest Rate for 24 months | C32: Shall we retrieve this as we can offer different tenor based on eligible amount? | E32: INTEREST_RATE_24 | F32: Requested Product | G32: Numeric | H32: 0 | I32: Numeric | J32: 4 | K32: 2 | L32: 0 | M32: M | N32: O | O32: I | P32: I | Q32: I
A33: =+A32+1 -> 31 | B33: Interest Rate for 36 months | C33: Shall we retrieve this as we can offer different tenor based on eligible amount? | E33: INTEREST_RATE_36 | F33: Requested Product | G33: Numeric | H33: 0 | I33: Numeric | J33: 4 | K33: 2 | L33: 0 | M33: M | N33: O | O33: I | P33: I | Q33: I
A34: =+A33+1 -> 32 | B34: Interest Rate for 48 months | C34: Shall we retrieve this as we can offer different tenor based on eligible amount? | E34: INTEREST_RATE_48 | F34: Requested Product | G34: Numeric | H34: 0 | I34: Numeric | J34: 4 | K34: 2 | L34: 0 | M34: M | N34: O | O34: I | P34: I | Q34: I
A35: =+A34+1 -> 33 | B35: Interest Rate for 60 months | C35: Shall we retrieve this as we can offer different tenor based on eligible amount? | E35: INTEREST_RATE_60 | F35: Requested Product | G35: Numeric | H35: 0 | I35: Numeric | J35: 4 | K35: 2 | L35: 0 | M35: M | N35: O | O35: I | P35: I | Q35: I
A36: =+A35+1 -> 34 | B36: C3.Policy Rules.Decision Category | C36: Calculated by ID and sent to Core System | D36: C3.Policy Rules.Decision Category | E36: C3_DECISION_CATEGORY | F36: ID Output | H36: " " | I36: Alpha | J36: 20 | K36: 0 | L36: 0 | M36: ID | N36: O | Q36: O
A37: =+A36+1 -> 35 | B37: Upsell Flag | C37: Customer is eligible for upsel or not | D37: Upsell_Flag | E37: UPSELL_FLG | F37: ID Output | G37: Y/N | H37: " " | I37: Alpha | J37: 1 | K37: 0 | L37: 0 | M37: ID | N37: O | Q37: O
A38: =+A37+1 -> 36 | B38: App.Bureau Score | C38: For future use | E38: BUREAU_SCORE | F38: Individual Bureau | G38: Numeric | H38: 0 | I38: Numeric | J38: 4 | K38: 0 | L38: 0 | M38: C | N38: O | P38: I | Q38: I
A39: =+A38+1 -> 37 | B39: App.Total Non-Card Balance | C39: For future use | E39: TOTAL_NON_CARD_BALANCE | F39: Individual Bureau | G39: Numeric | H39: 0 | I39: Numeric | J39: 12 | K39: 0 | L39: 0 | M39: C | N39: O | P39: I | Q39: I
A40: =+A39+1 -> 38 | B40: App.Max Duration Since Opening of an Open Card | C40: For future use | E40: MAX_DUR_SINCE_CC_OPEN | F40: Individual Bureau | G40: Numeric | H40: 0 | I40: Numeric | J40: 4 | K40: 0 | L40: 0 | M40: C | N40: O | P40: I | Q40: I
...

Sheet Parameters
A1: DD Name | B1: Channel | D1: City | F1: ID non-confirmation reason | H1: Other Income Type | J1: Country/ Nationality | L1: Education | N1: Employment Type | P1: Gender | R1: Marital Status | T1: Occupation | V1: Residence Type | X1: Payment Plan Type | Z1: Product Type | AB1: Risk Segmentation.Risk Segment | AD1: Currency | AF1: ID Type | AH1: WORK POSITION | AJ1: RESIDENCY | AL1: Loan Purpose | AN1: Credit Registry Status Fields
A2: # | B2: Possible Values | C2: Code | D2: Possible Values | E2: Code | F2: Possible Values | G2: Code | H2: Possible Values | I2: Code | J2: Possible Values | K2: Code | L2: Possible Values | M2: Code | N2: Possible Values | O2: Code | P2: Possible Values | Q2: Code | R2: Possible Values | S2: Code | T2: Possible Values | U2: Code | V2: Possible Values | W2: Code | X2: Possible Values | Y2: Code | Z2: Possible Values | AA2: Code | AB2: Code | AC2: Core System Value | AD2: Possible Values | AE2: Code | AF2: Possible Values | AG2: Code | AH2: Possible Values | AI2: Code | AJ2: Possible Values | AK2: Code | AL2: Possible Values | AM2: Code | AN2: Possible Values | AO2: Description
A3: 1 | B3: Branches | C3: BR | F3: System issues | G3: 01 | H3: Rent | I3: R | J3: Afganistan | K3: AF | L3: Primary | M3: P | N3: Unemployed | O3: U | P3: Male | Q3: M | R3: Married | S3: M | T3: AGENT - BROKER | U3: 01 | V3: Belongs to family | W3: F | X3: Equal monthly | Y3: E | Z3: Super Loan | AA3: SL | AB3: VL | AC3: Very low risk | AD3: ALL | AE3: 01 | AF3: Citizen ID | AG3: 1 | AH3: Owner/Partner | AI3: P | AJ3: Citizen | AK3: 1 | AL3: Home Loan | AM3: 1 | AN3: 0 | AO3: current
A4: 2 | B4: Direct Sales | C4: DS | F4: No ID document | G4: 02 | H4: Retirement | I4: E | J4: Almanya | K4: DE | L4: Doctorate | M4: D | N4: Retired | O4: R | P4: Female | Q4: F | R4: Single | S4: S | T4: AGRONOMIST | U4: 02 | V4: Belongs to someone else | W4: S | X4: Grace Period | Y4: S | Z4: Pensioner Loan | AA4: PL | AB4: LO | AC4: Low Risk | AD4: USD | AE4: 02 | AF4: Driving Licence | AG4: 2 | AH4: Top Manager | AI4: E | AJ4: Resident Permit Holder | AK4: 2 | AL4: House Contruction | AM4: 2 | AN4: 1,2,3 | AO4: delinquent
A5: 3 | B5: Website | C5: IN | H5: Spouse salary | I5: H | J5: Amerika Birleşik Devletleri | K5: US | L5: High School | M5: H | N5: Public Sector salaried | O5: P | R5: Divorced | S5: D | T5: ARCHAEOLOGIST | U5: 03 | V5: Belongs to customer | W5: C | X5: Interim payments | Y5: I | Z5: Home Loan | AA5: HL | AB5: ME | AC5: Medium Risk | AD5: CHF | AE5: 07 | AF5: Passport | AG5: 3 | AH5: Manager( up to Top Manager) | AI5: S | AJ5: Immigrant | AK5: 3 | AL5: Shop Loan | AM5: 3 | AN5: 4 | AO5: Legal
A6: 4 | B6: Call Center | C6: CC | H6: Family company share | I6: F | J6: Amerikan Samoa | K6: AS | L6: Masters | M6: M | N6: Private Sector salaried | O6: S | R6: Widowed | S6: W | T6: ARCHITECT - DESIGNER | U6: 04 | V6: Rent | W6: R | X6: Increasing payments | Y6: P | Z6: House Contruction | AA6: HC | AB6: HI | AC6: High Risj | AD6: CAD | AE6: 08 | AH6: Manager | AI6: M | AJ6: Non Resident | AK6: 4 | AL6: Home Improvement | AM6: 4 | AN6: 5 | AO6: closed
A7: 5 | B7: SMS | C7: SM | H7: Social Aid | I7: S | J7: Andorra | K7: AD | L7: University/College | M7: U | N7: Physical Person | O7: E | R7: Engaged/Co-Living | S7: E | T7: ARTIST | U7: 05 | V7: Co-Owner | W7: N | X7: Baloon payments | Y7: B | Z7: Shop Loan | AA7: SC | AB7: VH | AC7: Very High Risk | AD7: KWD | AE7: 09 | AH7: Officer (up to manager) | AI7: F | AL7: Health | AM7: 5 | AN7: 6 | AO7: write-off
A8: 6 | B8: eBanking | C8: EB | H8: Agriculture Income | I8: A | J8: Angola | K8: AO | N8: Housewife | O8: H | T8: LAWYER | U8: 06 | V8: Mortgage | W8: M | X8: Equal principal | Y8: Z | Z8: Home Improvement | AA8: HI | AD8: GBP | AE8: 10 | AH8: Laborer | AI8: L | AL8: Education | AM8: 6 | AN8: 7 | AO8: reversed
A9: 7 | B9: Mobile | C9: MB | H9: Remittance | I9: M | J9: Anguila | K9: AV | N9: Student | O9: T | T9: BANKER | U9: 07 | V9: Other | W9: O | X9: Flexible | Y9: F | Z9: Health | AA9: HT | AD9: SAR | AE9: 05 | AH9: Other | AI9: O | AL9: Turism | AM9: 7
A10: 8 | B10: ATM | C10: AT | H10: Military Pension | I10: P | J10: Anguilla | K10: AI | N10: Self-employed Professional | O10: L | T10: DEPUTY | U10: 08 | X10: Quarterly | Y10: 3 | Z10: Education | AA10: ED | AD10: JPY | AE10: 06 | AL10: Wedding | AM10: 8
A11: 9 | B11: Merchant | C11: ME | H11: Divorced Pension | I11: D | J11: Antarktika | K11: AQ | N11: Owner/Shareholder | O11: O | T11: DOCTOR | U11: 09 | X11: Semi-annually | Y11: 6 | Z11: Consumer Durable | AA11: CD | AD11: EUR | AE11: 03 | AL11: Land purchase | AM11: 9
A12: 10 | B12: Agent | C12: AG | H12: Health Pension | I12: L | J12: Antigua ve Barbuda | K12: AG | N12: Farmer | O12: F | T12: GENERAL DIRECTOR OF PUBLIC INSTITUTION | U12: 10 | X12: Bullet Payment | Y12: U | Z12: Technical Equipment | AA12: TE | AD12: AUD | AE12: 11 | AL12: Financial investment | AM12: 10
A13: 11 | H13: Honoraries & Bonuses | I13: B | J13: Arjantin | K13: AR | N13: NGO/ NPO (Non-government/Non-profit) | O13: N | T13: ECONOMIST | U13: 11 | Z13: Used Car | AA13: UC | AD13: IRR | AE13: 12 | AL13: State payments | AM13: 11
A14: 12 | H14: Other | I14: O | J14: Arnavutluk | K14: AL | N14: Immigrant | O14: M | T14: PHARMACIST | U14: 12 | Z14: New Car | AA14: NC | AD14: DKK | AE14: 13 | AL14: Consumer electronic | AM14: 12
A15: 13 | J15: Aruba | K15: AW | N15: Banking / Financial Institution salaried | O15: B | T15: FARMER | U15: 13 | Z15: Overdraft | AA15: OD | AD15: SEK | AE15: 14 | AL15: House Furnishing | AM15: 13
A16: 14 | J16: Ascention Adaları | K16: AC | T16: JOURNALIST | U16: 14 | Z16: Credit Card | AA16: CC | AD16: AED | AE16: 04 | AL16: Debt Purchase | AM16: 14
A17: 15 | J17: Avustralya | K17: AU | T17: GEOLOGIST | U17: 15 | Z17: Cash Collateral | AA17: CL | AD17: TRY | AE17: 15 | AL17: Technical Equipment | AM17: 15
A18: 16 | J18: Avusturya | K18: AT | T18: JUDGE | U18: 16 | Z18: Business Credit Card | AA18: BC | AL18: Used Car | AM18: 16
A19: 17 | J19: Azerbaycan | K19: AZ | T19: UNEMPLOYED | U19: 17 | Z19: Investment Loan | AA19: IL | AL19: New Car | AM19: 17
A20: 18 | J20: Bahama | K20: BS | T20: SELF-EMPLOYED | U20: 18 | Z20: Agro Loan | AA20: AL | AL20: Investment Loan | AM20: 18
A21: 19 | J21: Bahreyn | K21: BH | T21: INDUSTRIALIST | U21: 19 | Z21: Startup Loan | AA21: SU | AL21: Agro Loan | AM21: 19
A22: 20 | J22: Bangladeş | K22: BD | T22: NURSE | U22: 20 | Z22: Revolving Line | AA22: RL | AL22: Startup Loan | AM22: 20
A23: 21 | J23: Barbados | K23: BB | T23: INSPECTOR | U23: 21 | Z23: Inventory Loan | AA23: IV | AL23: Inventory Loan | AM23: 21
A24: 22 | J24: Batı Sahra | K24: EH | T24: ENGINEER | U24: 22 | Z24: Letter of Guarantee | AA24: LG | AL24: Consumer Refinance | AM24: 22
A25: 23 | J25: Belçika | K25: BE | T25: LAWYER | U25: 23 | Z25: Letter of Credit | AA25: LC
A26: 24 | J26: Belize | K26: BZ | T26: ACCOUNTANT | U26: 24 | Z26: Cheque Collateralized | AA26: CH
A27: 25 | J27: Benin | K27: BJ | T27: MATHEMATICIAN - PHYSICIST | U27: 25 | Z27: …
A28: 26 | J28: Bermuda | K28: BM | T28: MANAGER | U28: 26 | Z28: Staff Loan GPSL | AA28: EL
A29: 27 | J29: Beyaz Rusya (Belarus) | K29: BY | T29: EDUCATION STAFF | U29: 27 | Z29: Staff Loan SRCP/GPSL | AA29: ES
A30: 28 | J30: Bhutan | K30: BT | T30: MINORS | U30: 28 | Z30: Staff Loan HOME Loan | AA30: EH
A31: 29 | J31: Birleşik Arap Emirlikleri | K31: AE | T31: MASTER, CRAFT | U31: 29 | Z31: Staff Loan HOME Loan SRCP | AA31: ER
A32: 30 | J32: Birleşik Krallık | K32: UK | T32: EMPLOYEE(STATE) | U32: 30 | Z32: Consumer Refinance | AA32: CR
A33: 31 | J33: Bolivya | K33: BO | T33: HEALTH STAFF | U33: 31
A34: 32 | J34: Bosna Hersek | K34: BA | T34: EMPLOYEE(PRIVATE) | U34: 32
A35: 33 | J35: Botsvana | K35: BW | T35: NOTARY | U35: 33
A36: 34 | J36: Bouvet Adası | K36: BV | T36: MILLITARY STAFF | U36: 34
A37: 35 | J37: Brezilya | K37: BR | T37: TOURIST OPERATOR | U37: 35
A38: 36 | J38: Britanya Hint Okyanusu Toprağı | K38: IO | T38: LECTURER | U38: 36
A39: 37 | J39: Brunei Darüsselam | K39: BN | T39: RETIREE | U39: 37
A40: 38 | J40: Bulgaristan | K40: BG | T40: POLICE OFFICER | U40: 38
...

Sheet synthetic.py
A1: NAME | B1: FORMAT | C1: xLookup(Data Dictionary All) | D1: oculaires
A2: RANDOM_ID | B2: str(uuid.uuid4()) | C2: =_xlfn.XLOOKUP(A2,'Data Dictionary_All'!$E$1:$E$871,'Data Dictionary_All'!$E$1:$E$871,"n/a",0) -> RANDOM_ID | D2: 1
A3: CUSTOMER_RK | B3: i | C3: =_xlfn.XLOOKUP(A3,'Data Dictionary_All'!$E$1:$E$873,'Data Dictionary_All'!$E$1:$E$873,"n/a",0) -> n/a | D3: 0
A4: NAME | B4: fake.name() | C4: =_xlfn.XLOOKUP(A4,'Data Dictionary_All'!$E$1:$E$873,'Data Dictionary_All'!$E$1:$E$873,"n/a",1) -> NUM_CHARGE_OFF_36M | D4: 0
A5: ADDRESS | B5: fake.address().replace("\n", " ") | C5: =_xlfn.XLOOKUP(A5,'Data Dictionary_All'!$E$1:$E$873,'Data Dictionary_All'!$E$1:$E$873,"n/a",1) -> BEHAVIOUR_SCORE | D5: 0
A6: PHONE | B6: fake.phone_number() | C6: =_xlfn.XLOOKUP(A6,'Data Dictionary_All'!$E$1:$E$873,'Data Dictionary_All'!$E$1:$E$873,"n/a",1) -> PLEDGED_AMOUNT | D6: 0
A7: EMAIL | B7: fake.email() | C7: =_xlfn.XLOOKUP(A7,'Data Dictionary_All'!$E$1:$E$873,'Data Dictionary_All'!$E$1:$E$873,"n/a",1) -> EMAIL_INCONSISTENCY_FLG | D7: 0
A8: PERMANENT_RESIDENCE_FLG | B8: generate_flag(0.97) | C8: =_xlfn.XLOOKUP(A8,'Data Dictionary_All'!$E$1:$E$873,'Data Dictionary_All'!$E$1:$E$873,"n/a",1) -> PERMANENT_RESIDENT_FLG | D8: 1
A9: CUSTOMER_AGE | B9: generate_customer_age() | C9: =_xlfn.XLOOKUP(A9,'Data Dictionary_All'!$E$1:$E$873,'Data Dictionary_All'!$E$1:$E$873,"n/a",1) -> CUSTOMER_AGE | D9: 1
A10: CUSTOMER_STATUS | B10: generate_customer_status() | C10: =_xlfn.XLOOKUP(A10,'Data Dictionary_All'!$E$1:$E$873,'Data Dictionary_All'!$E$1:$E$873,"n/a",1) -> CUSTOMER_STATUS | D10: 1
A11: BUREAU_SCORE | B11: random.randint(601, 850) if random.random() < 0.6 else random.randint(250, 600) | C11: =_xlfn.XLOOKUP(A11,'Data Dictionary_All'!$E$1:$E$873,'Data Dictionary_All'!$E$1:$E$873,"n/a",1) -> BUREAU_SCORE | D11: 1
A12: TOTAL_NON_CARD_BALANCE | B12: random.randint(0, 50000) | C12: =_xlfn.XLOOKUP(A12,'Data Dictionary_All'!$E$1:$E$873,'Data Dictionary_All'!$E$1:$E$873,"n/a",1) -> TOTAL_NON_CARD_BALANCE | D12: 1
A13: BUREAU_INVESTIGATION_DATE_SINCE | B13: random.randint(0, 90) | C13: =_xlfn.XLOOKUP(A13,'Data Dictionary_All'!$E$1:$E$873,'Data Dictionary_All'!$E$1:$E$873,"n/a",1) -> BUREAU_INVESTIGATION_DATE_SINCE | D13: 1
A14: BUREAU_CARD_UTILIZATION | B14: round(random.uniform(0.0, 1.0), 2) | C14: =_xlfn.XLOOKUP(A14,'Data Dictionary_All'!$E$1:$E$873,'Data Dictionary_All'!$E$1:$E$873,"n/a",1) -> BUREAU_CARD_UTILIZATION | D14: 1
A15: DOCUMENTATION_COMPLETED_FLG | B15: generate_documentation_completed_flag(call_id) | C15: =_xlfn.XLOOKUP(A15,'Data Dictionary_All'!$E$1:$E$873,'Data Dictionary_All'!$E$1:$E$873,"n/a",1) -> DOCUMENTATION_COMPLETED_FLG | D15: 1
... A55: EMAIL_INCONSISTENCY_FLG | B55: generate_flag(0.02) | C55: =_xlfn.XLOOKUP(A55,'Data Dictionary_All'!$E$1:$E$873,'Data Dictionary_All'!$E$1:$E$873,"n/a",1) -> EMAIL_INCONSISTENCY_FLG | D55: 1
A56: IS_EMPLOYEE_FLG | B56: generate_flag(0.5), # 50% Y50% N | C56: =_xlfn.XLOOKUP(A56,'Data Dictionary_All'!$E$1:$E$873,'Data Dictionary_All'!$E$1:$E$873,"n/a",0) -> IS_EMPLOYEE_FLG | D56: 1
A57: DECLARED_INCOME | B57: random.randint(3000, 15000) | C57: =_xlfn.XLOOKUP(A57,'Data Dictionary_All'!$E$1:$E$873,'Data Dictionary_All'!$E$1:$E$873,"n/a",1) -> DECLARED_INCOME | D57: 1
A58: DOCUMENTED_INCOME | B58: documented_income | C58: =_xlfn.XLOOKUP(A58,'Data Dictionary_All'!$E$1:$E$873,'Data Dictionary_All'!$E$1:$E$873,"n/a",1) -> DOCUMENTED_INCOME | D58: 1
A59: TOTAL_EMPLOYMENT_DURATION | B59: random.randint(6, 240)in months | C59: =_xlfn.XLOOKUP(A59,'Data Dictionary_All'!$E$1:$E$873,'Data Dictionary_All'!$E$1:$E$873,"n/a",1) -> TOTAL_EMPLOYMENT_DURATION | D59: 1
A60: PLEDGED_AMOUNT | B60: generate_pledged_amount() | C60: =_xlfn.XLOOKUP(A60,'Data Dictionary_All'!$E$1:$E$873,'Data Dictionary_All'!$E$1:$E$873,"n/a",1) -> PLEDGED_AMOUNT | D60: 1
A61: VERIFIED_INCOME | B61: verified_income | C61: =_xlfn.XLOOKUP(A61,'Data Dictionary_All'!$E$1:$E$873,'Data Dictionary_All'!$E$1:$E$873,"n/a",1) -> VERIFIED_INCOME | D61: 1
A62: WPS_LIFETIME | B62: generate_wps_lifetime() | C62: =_xlfn.XLOOKUP(A62,'Data Dictionary_All'!$E$1:$E$873,'Data Dictionary_All'!$E$1:$E$873,"n/a",1) -> WPS_LIFETIME | D62: 1
A63: CUSTOMER_MONTHLY_EXPENSES | B63: customer_monthly_expenses | C63: =_xlfn.XLOOKUP(A63,'Data Dictionary_All'!$E$1:$E$873,'Data Dictionary_All'!$E$1:$E$873,"n/a",1) -> CUSTOMER_STATUS | D63: 0
A64: CALL_ID | B64: call_id | C64: =_xlfn.XLOOKUP(A64,'Data Dictionary_All'!$E$1:$E$873,'Data Dictionary_All'!$E$1:$E$873,"n/a",1) -> CALL_ID | D64: 1
A65: BAD | B65: generate_bad_flag()Only 6% bad customers | C65: =_xlfn.XLOOKUP(A65,'Data Dictionary_All'!$E$1:$E$873,'Data Dictionary_All'!$E$1:$E$873,"n/a",1) -> BEHAVIOUR_SCORE | D65: 0
